Workbook

Sheet Sheet1
A3: player of the match | B3: Count of player_of_the_match
A4: Shreyas Iyer | B4: 3
A5: Krunal Pandya | B5: 3
A6: Rohit Sharma | B6: 2
A7: Sunil Narine | B7: 2
A8: Ishan Kishan | B8: 2
A9: Prabhsimran Singh | B9: 2
A10: KL Rahul | B10: 2
A11: Prasidh Krishna | B11: 2
A12: Rajat Patidar | B12: 2
A13: Mitchell Starc | B13: 2
A14: Sai Sudarshan | B14: 2
A15: Will Jacks | B15: 2
... A56: Nicholas Pooran | B56: 1
A57: (blank)
A58: Grand Total | B58: 71

Sheet ipl_2026_analysis
A1: date | B1: venue | C1: team1 | D1: team2 | E1: stage | F1: match_winner | G1: player_of_the_match | H1: margin
A2: March 22,2025 | B2: Eden Gardens, Kolkata | C2: KKR | D2: RCB | E2: League | F2: RCB | G2: Krunal Pandya | H2: 7 wickets
A3: March 23,2025 | B3: Rajiv Gandhi International Stadium, Hyderabad | C3: SRH | D3: RR | E3: League | F3: SRH | G3: Ishan Kishan | H3: 44 runs
A4: March 23,2025 | B4: MA Chidambaram Stadium, Chennai | C4: CSK | D4: MI | E4: League | F4: CSK | G4: Noor Ahmad | H4: 4 wickets
A5: March 24,2025 | B5: ACA-VDCA Cricket Stadium, Vishakhapatnam | C5: DC | D5: LSG | E5: League | F5: DC | G5: Ashutosh Sharma | H5: 1 wicket
A6: March 25,2025 | B6: Narendra Modi Stadium, Ahmedabad | C6: GT | D6: PBKS | E6: League | F6: PBKS | G6: Shreyas Iyer | H6: 11 runs
A7: March 26,2025 | B7: Barsapara Stadium, Guwahati | C7: RR | D7: KKR | E7: League | F7: KKR | G7: Quinton de Kock | H7: 8 wickets
A8: March 27,2025 | B8: Rajiv Gandhi International Stadium, Hyderabad | C8: SRH | D8: LSG | E8: League | F8: LSG | G8: Shardul Thakur | H8: 5 wickets
A9: March 28,2025 | B9: MA Chidambaram Stadium, Chennai | C9: CSK | D9: RCB | E9: League | F9: RCB | G9: Rajat Patidar | H9: 50 runs
A10: March 29,2025 | B10: Narendra Modi Stadium, Ahmedabad | C10: GT | D10: MI | E10: League | F10: GT | G10: Prasidh Krishna | H10: 36 runs
A11: March 30,2025 | B11: ACA-VDCA Cricket Stadium, Vishakhapatnam | C11: DC | D11: SRH | E11: League | F11: DC | G11: Mitchell Starc | H11: 7 wickets
A12: March 30,2025 | B12: Barsapara Stadium, Guwahati | C12: RR | D12: CSK | E12: League | F12: RR | G12: Nitish Rana | H12: 6 runs
... A32: April 15,2025 | B32: New PCA Cricket Stadium, Mullanpur | C32: PBKS | D32: KKR | E32: League | F32: PBKS | G32: Yuzvendra Chahal | H32: 16 runs
A33: April 16,2025 | B33: Arun Jaitley Stadium, Delhi | C33: DC | D33: RR | E33: League | F33: DC | G33: Mitchell Starc
A34: April 17,2025 | B34: Wankhede Stadium, Mumbai | C34: MI | D34: SRH | E34: League | F34: MI | G34: Will Jacks | H34: 4 wickets
A35: April 18,2025 | B35: M. Chinnaswamy Stadium, Bangalore | C35: RCB | D35: PBKS | E35: League | F35: PBKS | G35: Tim David | H35: 5 wickets
A36: April 19,2025 | B36: Narendra Modi Stadium, Ahmedabad | C36: GT | D36: DC | E36: League | F36: GT | G36: Jos Buttler | H36: 7 wickets
A37: April 19,2025 | B37: Sawai Mansingh Stadium, Jaipur | C37: RR | D37: LSG | E37: League | F37: LSG | G37: Avesh Khan | H37: 2 runs
A38: April 20,2025 | B38: New PCA Cricket Stadium, Mullanpur | C38: PBKS | D38: RCB | E38: League | F38: PBKS | G38: Virat Kohli | H38: 7 wickets
A39: April 20,2025 | B39: Wankhede Stadium, Mumbai | C39: MI | D39: CSK | E39: League | F39: MI | G39: Rohit Sharma | H39: 9 wickets
A40: April 21,2025 | B40: Eden Gardens, Kolkata | C40: KKR | D40: GT | E40: League | F40: GT | G40: Shubman Gill | H40: 39 runs
A41: April 22,2025 | B41: Ekana Cricket Stadium, Lucknow | C41: LSG | D41: DC | E41: League | F41: DC | G41: Mukesh Kumar | H41: 8 wickets
A42: April 23,2025 | B42: Rajiv Gandhi International Stadium, Hyderabad | C42: SRH | D42: MI | E42: League | F42: MI | G42: Trent Boult | H42: 7 wickets
A43: April 24,2025 | B43: M. Chinnaswamy Stadium, Bangalore | C43: RCB | D43: RR | E43: League | F43: RCB | G43: Josh Hazlewood | H43: 11 runs
A44: April 25,2025 | B44: MA Chidambaram Stadium, Chennai | C44: CSK | D44: SRH | E44: League | F44: SRH | G44: Harshal Patel | H44: 5 wickets
A45: April 26,2025 | B45: Eden Gardens, Kolkata | C45: KKR | D45: PBKS | E45: League
A46: April 27,2025 | B46: Wankhede Stadium, Mumbai | C46: MI | D46: LSG | E46: League | F46: MI | G46: Will Jacks | H46: 54 runs
A47: April 27,2025 | B47: Arun Jaitley Stadium, Delhi | C47: DC | D47: RCB | E47: League | F47: RCB | G47: Krunal Pandya | H47: 6 wickets
A48: April 28,2025 | B48: Sawai Mansingh Stadium, Jaipur | C48: RR | D48: GT | E48: League | F48: RR | G48: Vaibhav Suryavanshi | H48: 8 wickets
A49: April 29,2025 | B49: Arun Jaitley Stadium, Delhi | C49: DC | D49: KKR | E49: League | F49: KKR | G49: Sunil Narine | H49: 14 runs
A50: April 30,2025 | B50: MA Chidambaram Stadium, Chennai | C50: CSK | D50: PBKS | E50: League | F50: PBKS | G50: Shreyas Iyer | H50: 4 wickets
A51: May 1,2025 | B51: Sawai Mansingh Stadium, Jaipur | C51: RR | D51: MI | E51: League | F51: MI | G51: Ryan Rickelton | H51: 100 runs
A52: May 2,2025 | B52: Narendra Modi Stadium, Ahmedabad | C52: GT | D52: SRH | E52: League | F52: GT | G52: Prasidh Krishna | H52: 38 runs
A53: May 3,2025 | B53: M. Chinnaswamy Stadium, Bangalore | C53: RCB | D53: CSK | E53: League | F53: RCB | G53: Romario Shepherd | H53: 2 runs
A54: May 4,2025 | B54: Eden Gardens, Kolkata | C54: KKR | D54: RR | E54: League | F54: KKR | G54: Andre Russell | H54: 1 run
A55: May 4,2025 | B55: HPCA Stadium, Dharamshala | C55: PBKS | D55: LSG | E55: League | F55: PBKS | G55: Prabhsimran Singh | H55: 37 runs
A56: May 5,2025 | B56: Rajiv Gandhi International Stadium, Hyderabad | C56: SRH | D56: DC | E56: League
A57: May 6,2025 | B57: Wankhede Stadium, Mumbai | C57: MI | D57: GT | E57: League | F57: GT | G57: Shubman Gill | H57: 3 wickets
A58: May 7,2025 | B58: Eden Gardens, Kolkata | C58: KKR | D58: CSK | E58: League | F58: CSK | G58: Noor Ahmad | H58: 2 wickets
A59: May 17,2025 | B59: M. Chinnaswamy Stadium, Bangalore | C59: RCB | D59: KKR | E59: League
...

Sheet Team Analysis
A1: Team | B1: Matches Played | C1: Matches won | D1: win%
A2: CSK | B2: =COUNTIF(ipl_2026_analysis!C:C,A2)+COUNTIF(ipl_2026_analysis!D:D,A2) -> 14 | C2: =COUNTIF(ipl_2026_analysis!F:F,A2) -> 4 | D2: =C2/B2 -> 0.28571429
A3: DC | B3: =COUNTIF(ipl_2026_analysis!C:C,A3)+COUNTIF(ipl_2026_analysis!D:D,A3) -> 14 | C3: =COUNTIF(ipl_2026_analysis!F:F,A3) -> 8 | D3: =C3/B3 -> 0.57142857
A4: GT | B4: =COUNTIF(ipl_2026_analysis!C:C,A4)+COUNTIF(ipl_2026_analysis!D:D,A4) -> 15 | C4: =COUNTIF(ipl_2026_analysis!F:F,A4) -> 9 | D4: =C4/B4 -> 0.6
A5: KKR | B5: =COUNTIF(ipl_2026_analysis!C:C,A5)+COUNTIF(ipl_2026_analysis!D:D,A5) -> 14 | C5: =COUNTIF(ipl_2026_analysis!F:F,A5) -> 5 | D5: =C5/B5 -> 0.35714286
A6: LSG | B6: =COUNTIF(ipl_2026_analysis!C:C,A6)+COUNTIF(ipl_2026_analysis!D:D,A6) -> 14 | C6: =COUNTIF(ipl_2026_analysis!F:F,A6) -> 6 | D6: =C6/B6 -> 0.42857143
A7: MI | B7: =COUNTIF(ipl_2026_analysis!C:C,A7)+COUNTIF(ipl_2026_analysis!D:D,A7) -> 16 | C7: =COUNTIF(ipl_2026_analysis!F:F,A7) -> 8 | D7: =C7/B7 -> 0.5
A8: PBKS | B8: =COUNTIF(ipl_2026_analysis!C:C,A8)+COUNTIF(ipl_2026_analysis!D:D,A8) -> 17 | C8: =COUNTIF(ipl_2026_analysis!F:F,A8) -> 11 | D8: =C8/B8 -> 0.64705882
A9: RCB | B9: =COUNTIF(ipl_2026_analysis!C:C,A9)+COUNTIF(ipl_2026_analysis!D:D,A9) -> 16 | C9: =COUNTIF(ipl_2026_analysis!F:F,A9) -> 10 | D9: =C9/B9 -> 0.625
A10: RR | B10: =COUNTIF(ipl_2026_analysis!C:C,A10)+COUNTIF(ipl_2026_analysis!D:D,A10) -> 14 | C10: =COUNTIF(ipl_2026_analysis!F:F,A10) -> 4 | D10: =C10/B10 -> 0.28571429
A11: SRH | B11: =COUNTIF(ipl_2026_analysis!C:C,A11)+COUNTIF(ipl_2026_analysis!D:D,A11) -> 14 | C11: =COUNTIF(ipl_2026_analysis!F:F,A11) -> 6 | D11: =C11/B11 -> 0.42857143
